Workbook

Sheet NOVIEMBRE 2025
A1: OCCALISTHENICSMX
A2: NOMBRE | C2: MEMBRESIA | D2: COSTO PLAN | E2: TIPO DE PLAN | F2: 45901 | G2: 45931 | H2: 45962 | I2: SAUNA | J2: OPEN GYM | K2: 5 VISITAS | L2: CLASES | M2: CLASES POR DIA
A3: TOÑITO OSNAYA | B3: 1 | C3: 720 | D3: 945 | E3: PLAN OC | F3: 945 | G3: 945 | H3: 945 | I3: ✅ | J3: ❌ | K3: ✅ | L3: TODAS | M3: UNA
A4: LIRIA VILLEGAS | B4: 2 | C4: 0 | D4: 945 | E4: PLAN OC | F4: 945 | G4: 945 | H4: 945 | I4: ✅ | J4: ❌ | K4: ✅ | L4: TODAS | M4: UNA
A5: VALERIA QUINTANA | B5: 3 | C5: 720 | D5: 945 | E5: PLAN OC | F5: 945 | G5: 945 | H5: 945 | I5: ✅ | J5: ❌ | K5: ✅ | L5: TODAS | M5: UNA
A6: ARLETTE ROMÁN | B6: 3 | C6: 720 | D6: 945 | E6: PLAN OC | F6: 945 | G6: 945 | H6: 945 | I6: ✅ | J6: ❌ | K6: ✅ | L6: TODAS | M6: UNA
A7: FERNANDA ALVA | B7: 5 | C7: 500 | D7: 995 | E7: PLAN OC | F7: 995 | G7: 995 | H7: 0 | I7: ✅ | J7: ❌ | K7: ✅ | L7: TODAS | M7: UNA
A8: PEDRO FLORES | B8: 11 | C8: 500 | D8: 945 | E8: PLAN OC | F8: 945 | G8: 945 | H8: 945 | I8: ✅ | J8: ❌ | K8: ✅ | L8: TODAS | M8: UNA
A9: LUIS ALBERTO | B9: 13 | C9: 720 | D9: 945 | E9: PLAN OC | F9: 945 | G9: 945 | H9: 945 | I9: ✅ | J9: ❌ | K9: ✅ | L9: TODAS | M9: UNA
A10: URIEL. CARDIEL | B10: 20 | C10: 90 | D10: 945 | E10: WELLHUB | F10: 945 | G10: 0 | H10: 0 | I10: ✅ | J10: ❌ | K10: ✅ | L10: TODAS | M10: UNA
A11: EDIT | B11: 18 | C11: 500 | D11: X | E11: 12 CLASES | F11: 0 | G11: 630 | I11: ❌ | J11: ❌ | K11: ❌ | L11: UNA | M11: UNA
A12: RODRIGO ALVA | B12: 24 | C12: 500 | D12: 995 | E12: PLAN OC | F12: 995 | G12: 995 | H12: 995 | I12: ✅ | J12: ❌ | K12: ✅ | L12: TODAS | M12: UNA
A13: BETTY | B13: 30 | C13: 500 | D13: X | E13: 12 CLASES | F13: 0 | G13: 630 | H13: 0 | I13: ❌ | J13: ❌ | K13: ❌ | L13: UNA | M13: UNA
A22: HÉCTOR NIETO | B22: 27 | C22: 150 | D22: 950 | E22: PLAN OC | F22: 950 | G22: 0 | H22: 0 | I22: ❌ | J22: ❌ | K22: ❌
A23: TOTAL | C23: {=SUM(C3:C22)} -> 5620 | F23: {=F3+F4+F5+F6+F7+F8+F9+F10+F12+F22+F25+C23} -> 15475 | G23: {=G3+G4+G9+G5+G6+G7+G8+G10+G12+G22+G11+G13+G28+G25+G26+G30+G31+G32} -> 10460.92 | H23: {=H3+H4+H9+H5+H6+H7+H8+H10+H12+H22+H11+H13+H28+H25+H26+H30+H31+H32+H37+H35+H34+H38+C37+C38+H39+H40+H41+C39+C40+C41+H36+C36+H33} -> 12395.02
A24: CLASE
A25: VALERIA MENA | C25: POR CLASE | D25: 75 | E25: 4 | F25: 300 | G25: {=D25*O60} -> 150 | H25: {=D25*P60} -> 300 | L25: TODAS | M25: $ POR CLASE
A26: APRIL | C26: POR CLASE | D26: 70 | E26: 3 | F26: X | G26: {=E26*D26} -> 210 | H26: {=D26*P48} -> 140
A27: WELLHUB | B27: WELLHUB. WELLHUB. WELLHUB. WELLHUB. WELLHUB. WELLHUB. WELLHUB. WELLHUB
A28: URIEL CARDIEL | C28: POR CHECK IN | D28: 171.82 | F28: X | G28: {=D28*O55} -> 1030.92 | H28: {=D28*P55} -> 1890.02 | L28: TODAS | M28: WELLHUB
A29: JUMPING | B29: MILCA. MILCA. MILCA. MILCA. MILCA. MILCA. MILCA. MILCA. MILCA. MILCA. MILCA
A30: PRIMA CHARLIE | C30: POR CLASE | D30: 50 | E30: 1 | F30: X | G30: {=E30*D30} -> 50 | H30: {=D30*P59} -> 50 | L30: UNA | M30: $ POR CLASE
A31: ESTHER | C31: POR CLASE | D31: 50 | E31: 1 | F31: X | G31: {=E31*D31} -> 50 | H31: {=D31*P57} -> 0 | L31: UNA | M31: $ POR CLASE
A32: HERMANA LIRIA | C32: POR CLASE | D32: 50 | E32: 1 | F32: X | G32: {=E32*D32} -> 50 | H32: {=D32*P58} -> 50 | L32: UNA | M32: $ POR CLASE
A33: AMIGA CYNTHIA | C33: X | D33: 75 | G33: {=E33*D33} -> 0 | H33: {=D33*P62} -> 75
A34: CYNTHIA JUÁREZ PEREZ | C34: X | D34: 75 | G34: {=E34*D34} -> 0 | H34: {=D34*P63} -> 150 | L34: UNA | M34: $ POR CLASE
A35: ANGELINA HERNÁNDEZ GARCIA | C35: X | D35: 75 | G35: {=E35*D35} -> 0 | H35: {=D35*P64} -> 150 | L35: UNA | M35: $ POR CLASE
A36: ALEJANDRA CUELLAR | B36: 15 | C36: 500 | D36: 75 | F36: X | G36: {=E36*D36} -> 0 | H36: {=D36*P65} -> 600
A37: ARYA CUELLAR | B37: 11 | C37: 250 | D37: 75 | F37: X | G37: {=E37*D37} -> 0 | H37: {=D37*P66} -> 150 | L37: UNA | M37: $ POR CLASE
A38: PATRICIO CUELLAR | B38: 11 | C38: 250 | D38: 75 | F38: X | G38: {=E38*D38} -> 0 | H38: {=D38*P67} -> 150 | L38: UNA | M38: $ POR CLASE
A39: ZULEIKA DE ZENTENO | B39: 14 | C39: 260 | D39: 75 | F39: X | G39: {=E39*D39} -> 0 | H39: {=D39*P68} -> 75 | L39: UNA | M39: $ POR CLASE
A40: DANIEL ALBERTANO. ZENTENO | B40: 14 | C40: 260 | D40: 75 | F40: X | G40: {=E40*D40} -> 0 | H40: {=D40*P69} -> 75 | L40: UNA | M40: $ POR CLASE
A41: NICOLE ZENTENO | B41: 14 | C41: 280 | D41: 75 | F41: X | G41: {=E41*D41} -> 0 | H41: {=D41*P70} -> 75 | L41: UNA | M41: $ POR CLASE
N43: CLASES TOMADAS
N44: X | O44: 45931 | P44: 45962 | V44: A cuenta
N45: EDITH 12 | O45: 4 | V45: 500
N46: BETTY 12 | O46: 0 | V46: 115
N47: TOÑITO OSNAYA | P47: 4
N48: APRIL | O48: 3 | P48: 2
N49: LIRIA VILLEGAS | P49: 4
...

Sheet DICIEMBRE 2025
A1: OCCALISTHENICSMX
A2: NOMBRE | C2: MEMBRESIA | D2: COSTO PLAN | E2: TIPO DE PLAN | F2: 45901 | G2: 45931 | H2: 45962 | I2: 45992 | J2: SAUNA | K2: OPEN GYM | L2: 5 VISITAS | M2: CLASES | N2: CLASES POR DIA
A3: TOÑITO OSNAYA | B3: 1 | C3: 720 | D3: 945 | E3: WELLHUB | F3: 945 | G3: 945 | H3: 945 | I3: 0 | J3: ✅ | K3: ❌ | L3: ✅ | M3: TODAS | N3: UNA
A4: LIRIA VILLEGAS | B4: 2 | C4: 0 | D4: 945 | E4: PLAN OC | F4: 945 | G4: 945 | H4: 945 | I4: 0 | J4: ✅ | K4: ❌ | L4: ✅ | M4: TODAS | N4: UNA
A5: VALERIA QUINTANA | B5: 3 | C5: 720 | D5: 945 | E5: PLAN OC | F5: 945 | G5: 945 | H5: 945 | I5: 945 | J5: ✅ | K5: ❌ | L5: ✅ | M5: TODAS | N5: UNA
A6: ARLETTE ROMÁN | B6: 3 | C6: 720 | D6: 945 | E6: PLAN OC | F6: 945 | G6: 945 | H6: 945 | I6: 945 | J6: ✅ | K6: ❌ | L6: ✅ | M6: TODAS | N6: UNA
A7: FERNANDA ALVA | B7: 5 | C7: 500 | D7: 995 | E7: PLAN OC | F7: 995 | G7: 995 | H7: 0 | I7: 0 | J7: ✅ | K7: ❌ | L7: ✅ | M7: TODAS | N7: UNA
A8: PEDRO FLORES | B8: 11 | C8: 500 | D8: 945 | E8: PLAN OC | F8: 945 | G8: 945 | H8: 945 | I8: 0 | J8: ✅ | K8: ❌ | L8: ✅ | M8: TODAS | N8: UNA
A9: LUIS ALBERTO | B9: 13 | C9: 720 | D9: 945 | E9: PLAN OC | F9: 945 | G9: 945 | H9: 945 | I9: 0 | J9: ✅ | K9: ❌ | L9: ✅ | M9: TODAS | N9: UNA
A10: URIEL. CARDIEL | B10: 20 | C10: 90 | D10: 945 | E10: WELLHUB | F10: 945 | G10: 0 | H10: 0 | I10: 0 | J10: ✅ | K10: ❌ | L10: ✅ | M10: TODAS | N10: UNA
A11: EDIT | B11: 18 | C11: 500 | D11: X | E11: 12 CLASES | F11: 0 | G11: 630 | H11: 630 | I11: 0 | J11: ❌ | K11: ❌ | L11: ❌ | M11: UNA | N11: UNA
A12: RODRIGO ALVA | B12: 24 | C12: 500 | D12: 995 | E12: PLAN OC | F12: 995 | G12: 995 | H12: 995 | I12: 995 | J12: ✅ | K12: ❌ | L12: ✅ | M12: TODAS | N12: UNA
A13: BETTY | B13: 30 | C13: 500 | D13: X | E13: 12 CLASES | F13: 0 | G13: 630 | H13: 0 | I13: 0 | J13: ❌ | K13: ❌ | L13: ❌ | M13: UNA | N13: UNA
A14: OSVALDO | B14: 16 | C14: 0 | D14: 400 | E14: OPEN GYM | F14: 0 | G14: 0 | H14: 0 | I14: 400
A21: TOTAL | I21: {=I3+I4+I5+I6+I7+I8+I9+I10+I11+I12+I13+I14} -> 3285
A23: HÉCTOR NIETO | B23: 27 | C23: 150 | D23: 950 | E23: PLAN OC | F23: 950 | G23: 0 | H23: 0 | I23: 0 | J23: ❌ | K23: ❌ | L23: ❌
A24: MENSUAL | C24: {=SUM(C3:C23)} -> 5620 | F24: 15475 | G24: 10460.92 | H24: 12395.02 | I24: {=I21+I32+I48} -> 10055.5
A25: TOTAL NETO | D25: {=F24+G24+H24+I24} -> 48386.44
A26: WELLHUB | B26: WELLHUB. WELLHUB. WELLHUB. WELLHUB. WELLHUB. WELLHUB. WELLHUB. WELLHUB
A27: APRIL | C27: POR CHECK IN | D27: 171.82 | I27: {=R54*D27} -> 515.46
A28: TOÑITO OSNAYA | C28: POR CHECK IN | D28: 171.82 | I28: {=D28*R53} -> 1890.02
A29: URIEL CARDIEL | C29: POR CHECK IN | D29: 171.82 | F29: X | G29: {=D29*P61} -> 1030.92 | H29: {=D29*Q61} -> 1890.02 | I29: {=D29*R61} -> 1890.02 | M29: TODAS | N29: WELLHUB
A30: DANIELA RAMÍREZ | C30: POR CHECK IN | D30: 171.82 | I30: {=D30*R78} -> 0
A31: ANDREA RODRÍGUEZ | C31: POR CHECK IN | D31: 171.82 | I31: {=D31*R79} -> 0
A32: TOTAL WELLHUB | G32: 1030.92 | H32: 1890.02 | I32: {=I27+I28+I29+I30+I31} -> 4295.5
A33: JUMPING | B33: MILCA. MILCA. MILCA. MILCA. MILCA. MILCA. MILCA. MILCA. MILCA. MILCA. MILCA
A34: PRIMA CHARLIE | C34: POR CLASE | D34: 50 | E34: 1 | F34: X | G34: {=E34*D34} -> 50 | H34: {=D34*Q65} -> 50 | I34: 0 | M34: UNA | N34: $ POR CLASE
A35: ESTHER | C35: POR CLASE | D35: 50 | E35: 1 | F35: X | G35: {=E35*D35} -> 50 | H35: {=D35*Q63} -> 0 | I35: 0 | M35: UNA | N35: $ POR CLASE
A36: HERMANA LIRIA | C36: POR CLASE | D36: 50 | E36: 1 | F36: X | G36: {=E36*D36} -> 50 | H36: {=D36*Q64} -> 50 | I36: 0 | M36: UNA | N36: $ POR CLASE
A37: VALERIA MENA | C37: POR CLASE | D37: 75 | E37: 4 | F37: 300 | G37: 150 | H37: {=D37*Q66} -> 150 | I37: 0 | M37: TODAS | N37: $ POR CLASE
A38: APRIL | C38: POR CLASE | D38: 70 | E38: 3 | F38: X | G38: 210 | H38: {=D38*Q54} -> 140 | I38: 0
A39: CYNTHIA JUÁREZ PEREZ | C39: X | D39: 75 | F39: X | G39: {=E39*D39} -> 0 | H39: {=D39*Q69} -> 150 | I39: {=D39*R69} -> 525 | M39: UNA | N39: $ POR CLASE
A40: ANGELINA HERNÁNDEZ GARCIA | C40: X | D40: 75 | F40: X | G40: {=E40*D40} -> 0 | H40: {=D40*Q70} -> 150 | I40: {=D40*R70} -> 375 | M40: UNA | N40: $ POR CLASE
A41: ALEJANDRA CUELLAR | B41: 15 | C41: 500 | D41: 75 | F41: X | G41: {=E41*D41} -> 0 | H41: {=D41*Q71} -> 450 | I41: {=D41*R71} -> 375
A42: ARYA CUELLAR | B42: 11 | C42: 250 | D42: 75 | F42: X | G42: {=E42*D42} -> 0 | H42: {=D42*Q72} -> 675 | I42: {=D42*R72} -> 600 | M42: UNA | N42: $ POR CLASE
A43: PATRICIO CUELLAR | B43: 11 | C43: 250 | D43: 75 | F43: X | G43: {=E43*D43} -> 0 | H43: {=D43*Q73} -> 525 | I43: {=D43*R73} -> 375 | M43: UNA | N43: $ POR CLASE
A44: ZULEIKA DE ZENTENO | B44: 14 | C44: 260 | D44: 75 | F44: X | G44: {=E44*D44} -> 0 | H44: {=D44*Q74} -> 75 | I44: 0 | M44: UNA | N44: $ POR CLASE
A45: DANIEL ALBERTANO. ZENTENO | B45: 14 | C45: 260 | D45: 75 | F45: X | G45: {=E45*D45} -> 0 | H45: {=D45*Q75} -> 75 | I45: 0 | M45: UNA | N45: $ POR CLASE
A46: NICOLE ZENTENO | B46: 14 | C46: 280 | D46: 75 | F46: X | G46: {=E46*D46} -> 0 | H46: {=D46*Q76} -> 75 | I46: 0 | M46: UNA | N46: $ POR CLASE
A47: CARLOS ERNESTO | D47: 75 | F47: X | G47: {=E47*D47} -> 0 | H47: {=D47*Q81} -> 0 | I47: {=D47*R77} -> 225
...

Sheet ENERO 2026
C2: X | D2: OCTUBRE | E2: NOVIEMBRE | F2: DICIEMBRE | G2: ENERO | K2: Visitas
C3: EDITH 12 | D3: 4 | E3: {='NOVIEMBRE 2025'!AN102+'NOVIEMBRE 2025'!AW127+'NOVIEMBRE 2025'!BP189+'NOVIEMBRE 2025'!CI251} -> 4 | F3: {='DICIEMBRE 2025'!AK120+'DICIEMBRE 2025'!BD190+'DICIEMBRE 2025'!BW263+'DICIEMBRE 2025'!CF300+'DICIEMBRE 2025'!CY373} -> 5 | G3: {=AJ93+BD160+BX237+CR321+DL404} -> 3
C4: BETTY 12 | D4: 0 | E4: {='NOVIEMBRE 2025'!CI252+'NOVIEMBRE 2025'!BP190+'NOVIEMBRE 2025'!AW128+'NOVIEMBRE 2025'!AN103} -> 0 | F4: {='DICIEMBRE 2025'!AK121+'DICIEMBRE 2025'!BD191+'DICIEMBRE 2025'!BW264+'DICIEMBRE 2025'!CF301+'DICIEMBRE 2025'!CY374} -> 1 | G4: {=AJ94+BD161+BX238+CR322+DL405} -> 2
C5: APRIL | D5: 3 | E5: {='NOVIEMBRE 2025'!AN105+'NOVIEMBRE 2025'!AW130+'NOVIEMBRE 2025'!BP192+'NOVIEMBRE 2025'!CI254} -> 2 | F5: {='DICIEMBRE 2025'!AK122+'DICIEMBRE 2025'!BD192+'DICIEMBRE 2025'!BW265+'DICIEMBRE 2025'!CF316+'DICIEMBRE 2025'!CY389} -> 3 | G5: {=AJ95+BD162+BX239+CR337+DL420} -> 7
C6: TOÑITO OSNAYA | E6: {='NOVIEMBRE 2025'!AN104+'NOVIEMBRE 2025'!AW129+'NOVIEMBRE 2025'!BP191+'NOVIEMBRE 2025'!CI253} -> 9 | F6: {='DICIEMBRE 2025'!AK138+'DICIEMBRE 2025'!BD208+'DICIEMBRE 2025'!BW281+'DICIEMBRE 2025'!CF318+'DICIEMBRE 2025'!CY391} -> 11 | G6: {=BD178+BX255+CR339+DL422} -> 13
C7: URIEL. CARDIEL | D7: 6 | E7: {='NOVIEMBRE 2025'!AN112+'NOVIEMBRE 2025'!AW137+'NOVIEMBRE 2025'!BP199+'NOVIEMBRE 2025'!CI261} -> 11 | F7: {='DICIEMBRE 2025'!AK137+'DICIEMBRE 2025'!BD207+'DICIEMBRE 2025'!BW280+'DICIEMBRE 2025'!CF317+'DICIEMBRE 2025'!CY390} -> 11 | G7: {=AJ110+BD177+BX254+CR338+DL421} -> 11
C8: DANIELA RAMÍREZ | D8: 0 | E8: 0 | F8: {='DICIEMBRE 2025'!BD209+'DICIEMBRE 2025'!BW282+'DICIEMBRE 2025'!CF319+'DICIEMBRE 2025'!CY392} -> 0
C9: ANDREA RODRÍGUEZ | D9: 0 | E9: 0 | F9: {='DICIEMBRE 2025'!BD210+'DICIEMBRE 2025'!BW283+'DICIEMBRE 2025'!CF320+'DICIEMBRE 2025'!CY393} -> 0
C10: LIRIA VILLEGAS | E10: {='NOVIEMBRE 2025'!CI255+'NOVIEMBRE 2025'!BP193+'NOVIEMBRE 2025'!AW131+'NOVIEMBRE 2025'!AN106} -> 6 | F10: {='DICIEMBRE 2025'!AK123+'DICIEMBRE 2025'!BD193+'DICIEMBRE 2025'!BW266+'DICIEMBRE 2025'!CF302+'DICIEMBRE 2025'!CY375} -> 6 | G10: {=AJ96+BD163+BX240+CR323+DL406} -> 10
C11: VALERIA QUINTANA | E11: {='NOVIEMBRE 2025'!AN107+'NOVIEMBRE 2025'!AW132+'NOVIEMBRE 2025'!BP194+'NOVIEMBRE 2025'!CI256} -> 1 | F11: {='DICIEMBRE 2025'!AK124+'DICIEMBRE 2025'!BD194+'DICIEMBRE 2025'!BW267+'DICIEMBRE 2025'!CF303+'DICIEMBRE 2025'!CY376} -> 0
C12: ARLETTE ROMÁN | E12: {='NOVIEMBRE 2025'!CI257+'NOVIEMBRE 2025'!BP195+'NOVIEMBRE 2025'!AW133+'NOVIEMBRE 2025'!AN108} -> 10 | F12: {='DICIEMBRE 2025'!AK125+'DICIEMBRE 2025'!BD195+'DICIEMBRE 2025'!BW268+'DICIEMBRE 2025'!CF304+'DICIEMBRE 2025'!CY377} -> 1 | G12: {=AJ98+BD165+BX242+CR325+DL408} -> 10 | K12: {=AL98+BF165+BZ242+CT325+DN408} -> 6
C13: FERNANDA ALVA | E13: 1 | F13: {='DICIEMBRE 2025'!AK126+'DICIEMBRE 2025'!BD196+'DICIEMBRE 2025'!BW269+'DICIEMBRE 2025'!CF305+'DICIEMBRE 2025'!CY378} -> 0
C14: PEDRO FLORES | E14: {='NOVIEMBRE 2025'!CI259+'NOVIEMBRE 2025'!BP197+'NOVIEMBRE 2025'!AW135+'NOVIEMBRE 2025'!AN110} -> 4 | F14: {='DICIEMBRE 2025'!AK127+'DICIEMBRE 2025'!BD197+'DICIEMBRE 2025'!BW270+'DICIEMBRE 2025'!CF306+'DICIEMBRE 2025'!CY379} -> 1
C15: LUIS ALBERTO | E15: {='NOVIEMBRE 2025'!CI260+'NOVIEMBRE 2025'!BP198+'NOVIEMBRE 2025'!AW136+'NOVIEMBRE 2025'!AN111} -> 5 | F15: {='DICIEMBRE 2025'!AK128+'DICIEMBRE 2025'!BD198+'DICIEMBRE 2025'!BW271+'DICIEMBRE 2025'!CF307+'DICIEMBRE 2025'!CY380} -> 0
C16: RODRIGO ALVA | D16: 0 | E16: {='NOVIEMBRE 2025'!CI262+'NOVIEMBRE 2025'!BP200+'NOVIEMBRE 2025'!AW138+'NOVIEMBRE 2025'!AN113} -> 7 | F16: {='DICIEMBRE 2025'!AK129+'DICIEMBRE 2025'!BD199+'DICIEMBRE 2025'!BW272+'DICIEMBRE 2025'!CF308+'DICIEMBRE 2025'!CY381} -> 3 | G16: {=AJ102+BD169+BX246+CR329+DL412} -> 9
C17: ESTHER | D17: 1 | E17: 0 | F17: {='DICIEMBRE 2025'!AK130+'DICIEMBRE 2025'!BD200+'DICIEMBRE 2025'!BW273+'DICIEMBRE 2025'!CF309+'DICIEMBRE 2025'!CY382} -> 0
C18: HERMANA LIRIA | D18: 1 | E18: 1 | F18: {='DICIEMBRE 2025'!AK131+'DICIEMBRE 2025'!BD201+'DICIEMBRE 2025'!BW274+'DICIEMBRE 2025'!CF310+'DICIEMBRE 2025'!CY383} -> 0
C19: PRIMA CHARLIE | D19: 1 | E19: 1 | F19: {='DICIEMBRE 2025'!AK132+'DICIEMBRE 2025'!BD202+'DICIEMBRE 2025'!BW275+'DICIEMBRE 2025'!CF311+'DICIEMBRE 2025'!CY384} -> 0
C20: VALERIA MENA | D20: 2 | E20: {='NOVIEMBRE 2025'!CI266+'NOVIEMBRE 2025'!BP204+'NOVIEMBRE 2025'!AW142+'NOVIEMBRE 2025'!AN117} -> 2 | F20: {='DICIEMBRE 2025'!AK133+'DICIEMBRE 2025'!BD203+'DICIEMBRE 2025'!BW276+'DICIEMBRE 2025'!CF312+'DICIEMBRE 2025'!CY385} -> 0 | G20: {=AJ106+BD173+BX250+CR333+DL416} -> 10
C21: Amiga Milka | D21: 0 | E21: 0 | F21: {='DICIEMBRE 2025'!AK140+'DICIEMBRE 2025'!BD212+'DICIEMBRE 2025'!BW285+'DICIEMBRE 2025'!CF322+'DICIEMBRE 2025'!CY395} -> 0
C22: Amiga Cynthia | D22: 0 | E22: 1 | F22: {='DICIEMBRE 2025'!AK141+'DICIEMBRE 2025'!BD213+'DICIEMBRE 2025'!BW286+'DICIEMBRE 2025'!CF323+'DICIEMBRE 2025'!CY396} -> 0
C23: CYNTHIA JUÁREZ PEREZ | D23: 0 | E23: 2 | F23: {='DICIEMBRE 2025'!AK142+'DICIEMBRE 2025'!BD214+'DICIEMBRE 2025'!BW287+'DICIEMBRE 2025'!CF324+'DICIEMBRE 2025'!CY397} -> 7 | G23: {=AJ115+BD184+BX261+CR345+DL428} -> 13
C24: ANGELINA HERNÁNDEZ GARCIA | D24: 0 | E24: 2 | F24: {='DICIEMBRE 2025'!AK143+'DICIEMBRE 2025'!BD215+'DICIEMBRE 2025'!BW288+'DICIEMBRE 2025'!CF325+'DICIEMBRE 2025'!CY398} -> 5 | G24: {=AJ116+BD185+BX262+CR346+DL429} -> 8
C25: VERO JUÁREZ | D25: 0 | E25: 0 | F25: 0 | G25: {=BX263+CR347+DL430} -> 6
C26: ALEJANDRA GARCIA | D26: 0 | E26: {='NOVIEMBRE 2025'!CI275+'NOVIEMBRE 2025'!BP212+'NOVIEMBRE 2025'!AW151} -> 6 | F26: {='DICIEMBRE 2025'!AK144+'DICIEMBRE 2025'!BD216+'DICIEMBRE 2025'!BW289+'DICIEMBRE 2025'!CF326+'DICIEMBRE 2025'!CY399} -> 5 | G26: {=AJ117+BD186+BX264+CR348+DL431} -> 0
C27: ARYA CUELLAR | D27: 0 | E27: {='NOVIEMBRE 2025'!AX152+'NOVIEMBRE 2025'!BQ213+'NOVIEMBRE 2025'!CI276} -> 9 | F27: {='DICIEMBRE 2025'!AK145+'DICIEMBRE 2025'!BD217+'DICIEMBRE 2025'!BW290+'DICIEMBRE 2025'!CF327+'DICIEMBRE 2025'!CY400} -> 8 | G27: {=AJ118+BD187+BX265+CR349+DL432} -> 5
C28: PATRICIO CUELLAR | D28: 0 | E28: {='NOVIEMBRE 2025'!CI277+'NOVIEMBRE 2025'!BP214+'NOVIEMBRE 2025'!AW153} -> 7 | F28: {='DICIEMBRE 2025'!AK146+'DICIEMBRE 2025'!BD218+'DICIEMBRE 2025'!BW291+'DICIEMBRE 2025'!CF328+'DICIEMBRE 2025'!CY401} -> 5 | G28: {=AJ119+BD188+BX266+CR350+DL433} -> 4
C29: ZULEIKA DE ZENTENO | D29: 0 | E29: 1 | F29: {='DICIEMBRE 2025'!AK147+'DICIEMBRE 2025'!BW292+'DICIEMBRE 2025'!CF329+'DICIEMBRE 2025'!BD219+'DICIEMBRE 2025'!CY402} -> 0 | G29: {=AJ107+BD174+BX251+CR334+DL417} -> 1
C30: DANIEL ALBERTANO. ZENTENO | D30: 0 | E30: 1 | F30: {='DICIEMBRE 2025'!AK136+'DICIEMBRE 2025'!BD206+'DICIEMBRE 2025'!BW279+'DICIEMBRE 2025'!CF315+'DICIEMBRE 2025'!CY388} -> 0 | G30: {=AJ109+BD176+BX253+CR336+DL419} -> 0
C31: NICOLE ZENTENO | D31: 0 | E31: 1 | F31: {='DICIEMBRE 2025'!AK135+'DICIEMBRE 2025'!BD205+'DICIEMBRE 2025'!BW278+'DICIEMBRE 2025'!CF314+'DICIEMBRE 2025'!CY387} -> 0 | G31: {=AJ108+BD175+BX252+CR335+DL418} -> 1
C32: CARLOS ERNESTO | D32: 0 | E32: 0 | F32: {='DICIEMBRE 2025'!BD220+'DICIEMBRE 2025'!BW293+'DICIEMBRE 2025'!CF330+'DICIEMBRE 2025'!CY403} -> 3 | G32: {=BD190+BX268+CR352+DL435} -> 4
C33: OSVALDO | D33: 0 | E33: 0 | F33: {='DICIEMBRE 2025'!BW294+'DICIEMBRE 2025'!CF331+'DICIEMBRE 2025'!CY404} -> 6 | G33: {=DL436+BX269+CR353} -> 3
C34: MIGUEL MARROQUÍN | D34: 0 | E34: 0 | F34: 0 | G34: {=CR354+DL437} -> 2
C35: IRMA GARCÍA | D35: 0 | E35: 0 | F35: 0 | G35: {=CR355+DL438} -> 4 | K35: {=CT355+DN438} -> 4
C36: ELENA | D36: 0 | E36: 0 | F36: 0 | G36: {=CR358+DL439} -> 9
C37: MARIA NAVARRO LARA | D37: 0 | E37: 0 | F37: 0 | G37: {=DL440} -> 1
C38: INVITADOS | D38: 0 | E38: 0 | F38: {='DICIEMBRE 2025'!AK148+'DICIEMBRE 2025'!BW295+'DICIEMBRE 2025'!CF332+'DICIEMBRE 2025'!CY405+'DICIEMBRE 2025'!BD221} -> 9 | G38: {=AJ121+BD191+BX274+CR358+DL441} -> 23
C39: TOTAL | D39: {=SUM(D3:D31)} -> 18 | E39: {=SUM(E3:E31)} -> 94 | F39: {=SUM(F3:F38)} -> 90 | G39: {=SUM(G3:G38)} -> 159 | H39: {=SUM(H3:H38)} -> 0 | I39: {=SUM(I3:I38)} -> 0 | J39: {=SUM(J3:J38)} -> 0 | K39: {=SUM(K3:K38)} -> 10
L41: OCCALISTHENICSMX
L42: NOMBRE | N42: MEMBRESIA | O42: COSTO PLAN | P42: TIPO DE PLAN | Q42: FINALIZA PLAN | R42: SEPTIEMBRE | S42: OCTUBRE | T42: NOVIEMBRE | U42: DICIEMBRE | V42: ENERO | W42: SAUNA | X42: OPEN GYM | Y42: VISITAS | Z42: CLASES | AA42: CLASES POR DIA | AB42: NUTRICIÓN
...

Sheet FEBRERO 2026
B2: OCCALISTHENICSMX
B3: NOMBRE | C3: DÍA DE PAGO | D3: MEMBRESIA | E3: COSTO PLAN | F3: TIPO DE PLAN | G3: FINALIZA PLAN | H3: ENERO | I3: FEBRERO | J3: SAUNA | K3: OPEN GYM | L3: VISITAS | M3: CLASES | N3: CLASES POR DIA | O3: NUTRICIÓN
B4: LIRIA VILLEGAS | C4: 19 ENERO | D4: PAGADA | E4: X | F4: SEMESTRE | G4: 19 JULIO | H4: 4500 | I4: 0 | J4: ✅ | K4: ✅ | L4: ✅ | M4: TODAS | N4: UNA | O4: ❌
B5: ARLETTE ROMÁN | C5: 3 NOVIEMBRE | D5: PAGADA | E5: 945 | F5: PLAN OC | H5: 945 | I5: 0 | J5: ✅ | K5: ✅ | L5: ✅ | M5: TODAS | N5: UNA | O5: ❌
B6: EDIT | C6: 18 NOVIEMBRE | D6: Debe $300 | E6: X | F6: 12 CLASES | H6: 0 | I6: 0 | J6: ❌ | K6: ✅ | L6: ❌ | M6: UNA | N6: UNA | O6: ❌
B7: RODRIGO ALVA | C7: 24 FEBRERO | D7: PAGADA | E7: 995 | F7: PLAN OC | G7: 24 MARZO | H7: 995 | I7: 0 | J7: ✅ | K7: ✅ | L7: ✅ | M7: TODAS | N7: UNA | O7: ❌
B8: OSVALDO | C8: 22 FEBRERO | D8: PAGADA | E8: 550 | F8: OPEN GYM | H8: 0 | I8: 0 | J8: ❌ | K8: ✅ | L8: ❌ | M8: NINGUNA | N8: NINGUNA | O8: ❌
B9: CYNTHIA JUÁREZ PEREZ | C9: 20 FEBRERO | D9: PAGADA | E9: 995 | F9: PLAN OC | G9: 20 MARZO | H9: 995 | I9: PENDIENTE | J9: ✅ | K9: ✅ | L9: ✅ | M9: TODAS | N9: UNA | O9: ❌
B10: MIGUEL MARROQUÍN | C10: 23 FEBRERO | D10: PAGADA | E10: 995 | F10: PLAN OC | G10: 23 MARZO | H10: 995 | I10: 995 | J10: ✅ | K10: ✅ | L10: ✅ | M10: TODAS | N10: UNA | O10: ❌
B11: IRMA GARCÍA | C11: 23 ENERO | D11: Debe $500 | E11: X | F11: SEMESTRE | G11: 23 JULIO | H11: 3500 | I11: 0 | J11: ✅ | K11: ✅ | L11: ✅ | M11: TODAS | N11: UNA | O11: ❌
B12: FERNANDA ALVA | C12: 17 FEBRERO | D12: PAGADA | E12: 995 | F12: PLAN OC | G12: 17 MARZO | H12: 0 | I12: 995 | J12: ✅ | K12: ✅ | L12: ✅ | M12: TODAS | N12: UNA | O12: ❌
B13: REBECA MELÉNDEZ | C13: 04 FEBRERO | D13: 500 | E13: 750 | F13: OPEN GYM | G13: 04 MARZO | H13: 0 | I13: 750 | J13: ❌ | K13: ✅ | L13: ❌ | M13: NINGUNA | N13: NINGUNA | O13: ❌
B14: GUADALUPE | C14: 04 FEBRERO | D14: 500 | E14: 2400 | F14: PAREJAS | G14: 04 MARZO | H14: 0 | I14: 1200 | J14: ✅ | K14: ✅ | L14: ✅ | M14: TODAS | N14: UNA | O14: ❌
B15: LAURA | C15: 09 FEBRERO | D15: 500 | E15: 0 | F15: PAREJAS | G15: 09 ABRIL | H15: 0 | I15: 1200
B16: ALEJANDRA CUELLAR | C16: 06 FEBREERO | D16: PAGADA | E16: 900 | F16: PAREJAS | G16: 06 ABRIL | H16: 0 | I16: 900 | J16: ✅ | K16: ✅ | L16: ✅ | M16: TODAS | N16: TODAS | O16: INBODY
B17: RODRIGO ALEJO PÉREZ | C17: 18 FEBRERO | D17: 300 | E17: 1200 | F17: POWERLIFTING | G17: 18 ABRIL | H17: 0 | I17: 1200 | J17: ❌ | K17: ✅ | L17: ❌ | M17: NINGUNA | N17: NINGUNA | O17: ❌
E18: 0 | F18: PAREJAS | H18: 0 | I18: 0
B19: SAUL JUAREZ | C19: 09 FEBRERO | D19: 250 | E19: 600 | F19: ESTUDIANTE VIP | G19: 09 MARZO | H19: 0 | I19: 600 | J19: ✅ | K19: ✅ | L19: ✅ | M19: TODAS | N19: TODAS | O19: INBODY
B20: MARTÍN JUÁREZ | C20: 10 FEBRERO | D20: 500 | E20: 1200 | F20: PAREJAS | G20: 09 ABRIL | I20: 1200 | J20: ✅ | K20: ✅ | L20: ✅ | M20: TODAS | N20: TODAS | O20: INBODY
B21: CLAUDIA NAVARRETE | C21: 11 FEBRERO | D21: 0 | E21: 250 | F21: SEMANAL | G21: 18 FEBRERO | I21: 250 | J21: ✅ | K21: ✅ | L21: ✅ | M21: TODAS | N21: TODAS | O21: INBODY
B22: MIGUEL MEJÍA ROJO | C22: 14 FEBRERO | D22: 750 | E22: 1200 | F22: PAREJAS | G22: 14 ABRIL | I22: 1200 | J22: ✅ | K22: ✅ | L22: ✅ | M22: TODAS | N22: TODAS | O22: INBODY
B23: ANTONIO DE OLMOS | C23: 16 FEBRERO | D23: 500 | E23: 995 | F23: PLAN OC | G23: 16 MARZO | I23: 995 | J23: ✅ | K23: ✅ | L23: ✅ | M23: TODAS | N23: TODAS | O23: INBODY
B24: CRISTINA CRUZ HERNÁNDEZ | C24: 20 FEBRERO | D24: 750 | E24: 1200 | F24: ALL CLUB | G24: 20 MARZO | I24: 1200
B25: DEREK ROJAS ROSAS | C25: 23 FEBRERO | D25: 500 | E25: 1200 | F25: PAREJAS | G25: 23 ABRIL | I25: 1200
B26: LUIS ROJAS RANGEL | C26: 23 FEBRERO | D26: 500 | E26: 1200 | F26: PAREJAS | G26: 23 ABRIL | I26: 1200
B27: TOTAL | E27: {=SUM(E4:E26)} -> 18570 | H27: {=H4+H5+H6+H7+H8+H9+H10+H11+H12+H13+H14} -> 11930 | I27: {=SUM($I$4:$I$26)} -> 15085
B28: INACTIVOS
D29: 0 | E29: 0 | F29: PLAN OC
B30: MENSUAL | D30: {=SUM(D4:D29)} -> 5550 | H30: 22062.76 | I30: {=D30+I27+I36+I51} -> 28167.74
B31: TOTAL NETO | E31: {='ENERO 2026'!O65+I30} -> 105401.94
B32: WELLHUB | C32: WELLHUB. WELLHUB. WELLHUB. WELLHUB. WELLHUB. WELLHUB. WELLHUB. WELLHUB
B33: APRIL | D33: POR CHECK IN | E33: 171.82 | H33: 515.46 | I33: {=E33*T55} -> 171.82 | N33: WELLHUB
B34: TOÑITO OSNAYA | D34: POR CHECK IN | E34: 171.82 | H34: 1890.02 | I34: 1890 | M34: TODAS | N34: WELLHUB
B35: URIEL CARDIEL | D35: POR CHECK IN | E35: 171.82 | H35: 1890.02 | I35: {=E35*T69} -> 1030.92 | N35: WELLHUB
B36: TOTAL WELLHUB | H36: 4295.5 | I36: {=I33+I34+I35} -> 3092.74 | N36: WELLHUB
B37: POR CLASE | C37: POR CLASE | M37: TODAS | N37: $ POR CLASE
B38: VALERIA MENA | C38: 19 ENERO | D38: PAGADA | E38: 50 | F38: SEMANAL | G38: 02 FEBRERO | H38: 500 | I38: 0 | M38: UNA | N38: $ POR CLASE
B39: ANGELINA HERNÁNDEZ GARCIA | D39: PAGADA | E39: 75 | F39: POR CLASE | H39: 675 | I39: {=E39*T86} -> 1200 | M39: UNA | N39: $ POR CLASE
B40: CYNTHIA JUÁREZ PEREZ | C40: 23 FEBRERO | D40: PAGADA | E40: 75 | F40: POR CLASE | H40: 0 | I40: {=E40*U62} -> 150
B41: VERO JUÁREZ | C41: 21 ENERO | D41: PAGADA | E41: 75 | F41: POR CLASE | H41: 450 | I41: {=E41*T87} -> 825
...

Sheet MARZO 2026
B2: OCCALISTHENICSMX
B3: NOMBRE | C3: DÍA DE PAGO | D3: MEMBRESIA | E3: COSTO PLAN | F3: TIPO DE PLAN | G3: FINALIZA PLAN | H3: ENERO | I3: FEBRERO | J3: MARZO | K3: SAUNA | L3: OPEN GYM | M3: VISITAS | N3: CLASES | O3: CLASES POR DIA | P3: NUTRICIÓN
B4: LIRIA VILLEGAS | C4: 19 ENERO | D4: PAGADA | E4: X | F4: SEMESTRE | G4: 19 JULIO | H4: 4500 | I4: 0 | J4: 0 | K4: ✅ | L4: ✅ | M4: ✅ | N4: TODAS | O4: UNA | P4: ❌
B5: ARLETTE ROMÁN | C5: 3 NOVIEMBRE | D5: PAGADA | E5: 945 | F5: PLAN OC | H5: 945 | I5: 0 | J5: 0 | K5: ✅ | L5: ✅ | M5: ✅ | N5: TODAS | O5: UNA | P5: ❌
B6: EDIT | C6: 18 NOVIEMBRE | D6: Debe $300 | E6: X | F6: 12 CLASES | H6: 0 | I6: 0 | J6: 0 | K6: ❌ | L6: ✅ | M6: ❌ | N6: UNA | O6: UNA | P6: ❌
B7: OSVALDO | C7: 22 FEBRERO | D7: PAGADA | E7: 550 | F7: OPEN GYM | H7: 0 | I7: 0 | J7: 0 | K7: ❌ | L7: ✅ | M7: ❌ | N7: NINGUNA | O7: NINGUNA | P7: ❌
B8: MIGUEL MARROQUÍN | C8: 23 FEBRERO | D8: PAGADA | E8: 995 | F8: CALISTHENICS | G8: 23 MARZO | H8: 995 | I8: 995 | J8: 0 | K8: ✅ | L8: ✅ | M8: ✅ | N8: TODAS | O8: UNA | P8: ❌
B9: IRMA GARCÍA | C9: 23 ENERO | D9: Debe $500 | E9: X | F9: SEMESTRE | G9: 23 JULIO | H9: 3500 | I9: 0 | J9: 0 | K9: ✅ | L9: ✅ | M9: ✅ | N9: TODAS | O9: UNA | P9: ❌
B10: FERNANDA ALVA | C10: 17 FEBRERO | D10: PAGADA | E10: 995 | F10: PLAN OC | G10: 17 MARZO | H10: 0 | I10: 995 | J10: 0 | K10: ✅ | L10: ✅ | M10: ✅ | N10: TODAS | O10: UNA | P10: ❌
B11: REBECA MELÉNDEZ | C11: 04 FEBRERO | D11: PAGADA | E11: 750 | F11: OPEN GYM | G11: 04 MARZO | H11: 0 | I11: 750 | J11: 0 | K11: ❌ | L11: ✅ | M11: ❌ | N11: NINGUNA | O11: NINGUNA | P11: ❌
B12: GUADALUPE | C12: 04 FEBRERO | D12: PAGADA | E12: 995 | F12: PAREJAS | G12: 04 MARZO | H12: 0 | I12: 1200 | J12: 0 | K12: ✅ | L12: ✅ | M12: ✅ | N12: ILIMITADAS | O12: UNA | P12: ❌
B13: LAURA | C13: 09 FEBRERO | D13: PAGADA | E13: 995 | F13: PAREJAS | G13: 09 ABRIL | H13: 0 | I13: 1200 | J13: 0 | K13: ✅ | L13: ✅ | M13: ✅ | N13: ILIMITADAS | O13: UNA | P13: ❌
B14: ALEJANDRA CUELLAR | C14: 06 FEBREERO | D14: PAGADA | E14: 450 | F14: PAREJAS | G14: 06 ABRIL | H14: 0 | I14: 900 | J14: 0 | K14: ✅ | L14: ✅ | M14: ✅ | N14: ILIMITADAS | O14: TODAS | P14: INBODY
B15: RODRIGO ALEJO PÉREZ | C15: 18 FEBRERO | D15: PAGADA | E15: 1200 | F15: POWERLIFTING | G15: 18 ABRIL | H15: 0 | I15: 1200 | J15: 0 | K15: ❌ | L15: ✅ | M15: ❌ | N15: NINGUNA | O15: NINGUNA | P15: ❌
B16: FELISA HERRADA MARTÍNEZ | C16: 03 MARZO | D16: 750 | E16: 850 | F16: CALISTHENICS | G16: 03 ABRIL | H16: 0 | I16: 0 | J16: 850 | K16: ❌ | L16: ✅ | M16: ❌ | N16: NINGUNA | O16: NINGUNA | P16: ❌
B17: SAUL JUAREZ | C17: 09 FEBRERO | D17: PAGADA | E17: 600 | F17: POWERLIFTING | G17: 09 MARZO | H17: 0 | I17: 600 | J17: 600 | K17: ✅ | L17: ✅ | M17: ✅ | N17: ILIMITADAS | O17: ILIMITADAS | P17: INBODY
B18: MARTÍN JUÁREZ | C18: 10 FEBRERO | D18: PAGADA | E18: 1200 | F18: POWERLIFTING | G18: 09 ABRIL | H18: 0 | I18: 1200 | J18: 0 | K18: ✅ | L18: ✅ | M18: ✅ | N18: ILIMITADAS | O18: ILIMITADAS | P18: INBODY
B19: CLAUDIA NAVARRETE | C19: 11 FEBRERO | D19: PAGADA | E19: 250 | F19: SEMANAL | G19: 18 FEBRERO | H19: 0 | I19: 250 | J19: 0 | K19: ✅ | L19: ✅ | M19: ✅ | N19: ILIMITADAS | O19: ILIMITADAS | P19: INBODY
B20: MIGUEL MEJÍA ROJO | C20: 14 FEBRERO | D20: PAGADA | E20: 1200 | F20: POWERLIFTING | G20: 14 ABRIL | H20: 0 | I20: 1200 | J20: 0 | K20: ✅ | L20: ✅ | M20: ✅ | N20: ILIMITADAS | O20: ILIMITADAS | P20: INBODY
B21: ANTONIO DE OLMOS | C21: 16 FEBRERO | D21: PAGADA | E21: 995 | F21: PLAN OC | G21: 16 MARZO | H21: 0 | I21: 995 | J21: 995 | K21: ✅ | L21: ✅ | M21: ✅ | N21: ILIMITADAS | O21: ILIMITADAS | P21: INBODY
B22: CRISTINA CRUZ HERNÁNDEZ | C22: 20 FEBRERO | D22: PAGADA | E22: 1200 | F22: ALL CLUB | G22: 20 MARZO | H22: 0 | I22: 1200 | J22: 0 | K22: ✅ | L22: ✅ | M22: ✅ | N22: ILIMITADAS | O22: ILIMITADAS | P22: INBODY
B23: DEREK ROJAS ROSAS | C23: 23 FEBRERO | D23: PAGADA | E23: 1200 | F23: PAREJAS | G23: 23 ABRIL | H23: 0 | I23: 1200 | J23: 0 | K23: ✅ | L23: ✅ | M23: ✅ | N23: ILIMITADAS | O23: ILIMITADAS | P23: INBODY
B24: LUIS ROJAS RANGEL | C24: 23 FEBRERO | D24: PAGADA | E24: 1200 | F24: PAREJAS | G24: 23 ABRIL | H24: 0 | I24: 1200 | J24: 0 | K24: ✅ | L24: ✅ | M24: ✅ | N24: ILIMITADAS | O24: ILIMITADAS | P24: INBODY
B25: XIMENA AÑORVE FLORES | C25: 02 MARZO | D25: 300 | E25: 1200 | F25: ALL CLUB | G25: 02 ABRIL | H25: 0 | I25: 0 | J25: 1200 | K25: ✅ | L25: ✅ | M25: ✅ | N25: ILIMITADAS | O25: ILIMITADAS | P25: INBODY
B26: LUIS ERNESTO MARTÍNEZ VELAZCO | C26: 18 MARZO | D26: 800 | E26: 1200 | F26: ALL CLUB | G26: 18 ABRIL | H26: 0 | I26: 0 | J26: 1200 | K26: ✅ | L26: ✅ | M26: ✅ | N26: ILIMITADAS | O26: ILIMITADAS | P26: INBODY
B27: ZEUS YAEL NEVÁREZ OLIVARES | C27: 18 MARZO | D27: 800 | E27: 1200 | F27: ALL CLUB | G27: 18 ABRIL | H27: 0 | I27: 0 | J27: 1200 | K27: ✅ | L27: ✅ | M27: ✅ | N27: ILIMITADAS | O27: ILIMITADAS | P27: INBODY
B28: DIEGO MORENO HERNÁNDEZ | C28: 09 MARZO | D28: 750 | E28: 1200 | F28: ALL CLUB | G28: 09 ABRIL | H28: 0 | I28: 0 | J28: 1200 | K28: ✅ | L28: ✅ | M28: ✅ | N28: ILIMITADAS | O28: ILIMITADAS | P28: INBODY
B29: CARLOS SÁNCHEZ LARA | C29: 09 MARZO | D29: 300 | E29: 1200 | F29: POWERLIFTING | G29: 09 ABRIL | H29: 0 | I29: 0 | J29: 600 | K29: ✅ | L29: ✅ | M29: ✅ | N29: ILIMITADAS | O29: ILIMITADAS | P29: INBODY
B30: DANIEL VÁZQUEZ CEDILLO | C30: 10 MARZO | D30: 300 | E30: 1350 | F30: ALL CLUB | G30: 10 ABRIL | H30: 0 | I30: 0 | J30: 1350 | K30: ✅ | L30: ✅ | M30: ✅ | N30: ILIMITADAS | O30: ILIMITADAS | P30: INBODY
B31: JONATHAN PALETA TULA | C31: 16 MARZO | D31: 300 | E31: 1350 | F31: ALL CLUB | G31: 16 ABRIL | H31: 0 | I31: 0 | J31: 1350 | K31: ✅ | L31: ✅ | M31: ✅ | N31: ILIMITADAS | O31: ILIMITADAS | P31: INBODY
B32: CYNTHIA JUÁREZ PEREZ | C32: 23 MARZO | D32: PAGADA | E32: 995 | F32: PLAN OC | G32: 23 ABRIL | H32: 995 | I32: 0 | J32: 995 | K32: ✅ | L32: ✅ | M32: ✅ | N32: CLASE | O32: UNA | P32: ❌
B33: IVÁN CAMARENA | C33: 30 MARZO | D33: 300 | E33: 1550 | F33: ALL CLUB | G33: 30 ABRIL | H33: 0 | I33: 0 | J33: 1550 | K33: ✅ | L33: ✅ | M33: ✅ | N33: ILIMITADAS | O33: ILIMITADAS | P33: INBODY
B34: MEJIA VILLALOBOS ARTURO | C34: 31 MARZO | D34: 500 | E34: 1350 | F34: ALL CLUB | G34: 01 ABRIL | J34: 1350 | K34: ✅ | L34: ✅ | M34: ✅ | N34: ILIMITADAS | O34: ILIMITADAS | P34: INBODY
B35: MEJÍA DÍAZ OMAR | C35: 31 MARZO | D35: 500 | E35: 1350 | F35: ALL CLUB | G35: 01 ABRIL | J35: 1350 | K35: ✅ | L35: ✅ | M35: ✅ | N35: ILIMITADAS | O35: ILIMITADAS | P35: INBODY
B36: TOTAL | E36: {=SUM(E4:E35)} -> 30515 | H36: 11930 | I36: {=SUM($I$4:$I$24)} -> 15085 | J36: {=SUM(J4:J35)} -> 15790
B37: MENSUAL | D37: {=D25+D26+D27+D16+D28+D29+D30+D31+D33+D35+D34} -> 5600 | H37: 21387.76 | I37: 28167.74 | J37: {=J36+D37+J43+J61} -> 32682.78
B38: TOTAL NETO | E38: {='FEBRERO 2026'!E31+J37} -> 138084.72
B39: WELLHUB | C39: WELLHUB. WELLHUB. WELLHUB. WELLHUB. WELLHUB. WELLHUB. WELLHUB. WELLHUB
B40: APRIL | D40: POR CHECK IN | E40: 171.82 | H40: 1202.74 | I40: {=E40*V70} -> 171.82 | J40: {=E40*W70} -> 1202.74 | O40: WELLHUB
B41: TOÑITO OSNAYA | D41: POR CHECK IN | E41: 171.82 | H41: 1890 | I41: 1890 | J41: 1890.02 | N41: TODAS | O41: WELLHUB
...

Sheet ABRIL 2026
B2: OCCALISTHENICSMX
B3: NOMBRE | C3: DÍA DE PAGO | D3: MEMBRESIA | E3: COSTO PLAN | F3: TIPO DE PLAN | G3: FINALIZA PLAN | H3: ENERO | I3: FEBRERO | J3: MARZO | K3: ABRIL | L3: SAUNA | M3: OPEN GYM | N3: VISITAS | O3: CLASES | P3: CLASES POR DIA | Q3: NUTRICIÓN
B4: LIRIA VILLEGAS | C4: 19 ENERO | D4: PAGADA | E4: X | F4: SEMESTRE | G4: 19 JULIO | H4: 4500 | I4: 0 | J4: 0 | L4: ✅ | M4: ✅ | N4: ✅ | O4: TODAS | P4: UNA | Q4: ❌
B5: OSVALDO | C5: 22 FEBRERO | D5: PAGADA | E5: $ | F5: OPEN GYM | H5: 0 | I5: 0 | J5: 0 | L5: ❌ | M5: ✅ | N5: ❌ | O5: NINGUNA | P5: NINGUNA | Q5: ❌
B6: IRMA GARCÍA | C6: 23 ENERO | D6: Debe $500 | E6: X | F6: SEMESTRE | G6: 23 JULIO | H6: 3500 | I6: 0 | J6: 0 | L6: ✅ | M6: ✅ | N6: ✅ | O6: TODAS | P6: UNA | Q6: ❌
B7: ALEJANDRA CUELLAR | C7: 06 ABRIL | D7: PAGADA | E7: 450 | F7: PAREJAS | G7: 06 MAYO | H7: 0 | I7: 900 | J7: 0 | L7: ✅ | M7: ✅ | N7: ✅ | O7: ILIMITADAS | P7: TODAS | Q7: INBODY
B8: FELISA HERRADA MARTÍNEZ | C8: 03 ABRIL | D8: PAGADA | E8: 850 | F8: CALISTHENICS | G8: 03 MAYO | H8: 0 | I8: 0 | J8: 850 | K8: 850 | L8: ❌ | M8: ✅ | N8: ❌ | O8: NINGUNA | P8: NINGUNA | Q8: ❌
B9: MIGUEL MEJÍA ROJO | C9: 14 ABRIL | D9: PAGADA | E9: 899 | F9: POWERLIFTING | G9: 14 MAYO | H9: 0 | I9: 1200 | J9: 0 | K9: 899 | L9: ✅ | M9: ✅ | N9: ✅ | O9: ILIMITADAS | P9: ILIMITADAS | Q9: INBODY
B10: XIMENA AÑORVE FLORES | C10: 01 ABRIL | D10: PAGADA | E10: 1200 | F10: ALL CLUB | G10: 01 MAYO | H10: 0 | I10: 0 | J10: 1200 | K10: 1200 | L10: ✅ | M10: ✅ | N10: ✅ | O10: ILIMITADAS | P10: ILIMITADAS | Q10: INBODY
B11: DIEGO MORENO HERNÁNDEZ | C11: 09 ABRIL | D11: PAGADA | E11: 1200 | F11: ALL CLUB | G11: 09 MAYO | H11: 0 | I11: 0 | J11: 1200 | K11: 1200 | L11: ✅ | M11: ✅ | N11: ✅ | O11: ILIMITADAS | P11: ILIMITADAS | Q11: INBODY
B12: CYNTHIA JUÁREZ PEREZ | C12: 23 ABRIL | D12: PAGADA | E12: 995 | F12: PLAN OC | G12: 23 MAYO | H12: 995 | I12: 0 | J12: 995 | K12: 995 | L12: ✅ | M12: ✅ | N12: ✅ | O12: CLASE | P12: UNA | Q12: ❌
B13: IVÁN CAMARENA | C13: 03 ABRIL | D13: PAGADA | E13: 1550 | F13: 12 CLASES | G13: 03 MAYO | H13: 0 | I13: 0 | J13: 1550 | L13: ✅ | M13: ✅ | N13: ✅ | O13: ILIMITADAS | P13: ILIMITADAS | Q13: INBODY
B14: MEJIA VILLALOBOS ARTURO | C14: 30 ABRIL | D14: PAGADA | E14: 1350 | F14: ALL CLUB | G14: 30 MAYO | H14: 0 | I14: 0 | J14: 1350 | L14: ✅ | M14: ✅ | N14: ✅ | O14: ILIMITADAS | P14: ILIMITADAS | Q14: INBODY
B15: MEJÍA DÍAZ OMAR | C15: 30 ABRIL | D15: PAGADA | E15: 1350 | F15: ALL CLUB | G15: 30 MAYO | H15: 0 | I15: 0 | J15: 1350 | L15: ✅ | M15: ✅ | N15: ✅ | O15: ILIMITADAS | P15: ILIMITADAS | Q15: INBODY
B16: ROCIO BRAMBILA | C16: 02 ABRIL | D16: PAGADA | E16: 500 | F16: CALISTHENICS | G16: 02 MAYO | H16: 0 | I16: 0 | J16: 0 | K16: 500 | L16: ✅ | M16: ✅ | N16: ✅ | O16: ILIMITADAS | P16: ILIMITADAS | Q16: INBODY
B17: WILLY SÁNCHEZ | C17: 20 ABRIL | D17: 300 | E17: 600 | F17: OC- GYM BASIC | G17: 20 MAYO | K17: 600 | L17: ❌ | M17: ✅ | N17: ❌ | O17: NINGUNA | P17: NINGUNA | Q17: ❌
B18: JESICA ACEVEDO | D18: 300 | E18: 600 | F18: OC- GYM BASIC | H18: 0 | I18: 0 | J18: 0 | L18: ❌ | M18: ✅ | N18: ❌ | O18: NINGUNA | P18: NINGUNA | Q18: ❌
B19: TAKAO KATAGIRI | C19: 20 ABRIL | D19: 300 | E19: 750 | F19: OC- GYM BASIC | G19: 20 MAYO | K19: 750 | L19: ❌ | M19: ✅ | N19: ❌ | O19: NINGUNA | P19: NINGUNA | Q19: ❌
B21: TOTAL | E21: {=SUM(E4:E19)} -> 12294 | H21: 11930 | I21: {=SUM($I$4:$I$9)} -> 2100 | J21: {=SUM(J4:J15)} -> 8495 | K21: {=SUM(K4:K19)} -> 6994
B22: MENSUAL | H22: 21387.76 | I22: 28167.74 | J22: 32682.78 | K22: {=K21+D23+K29+K41+M44} -> 13733.12
B23: TOTAL NETO | D23: {=D18+D17+D19} -> 900 | E23: {='FEBRERO 2026'!E31+'MARZO 2026'!J37+K22} -> 151817.84
B24: WELLHUB | C24: WELLHUB. WELLHUB. WELLHUB. WELLHUB. WELLHUB. WELLHUB. WELLHUB. WELLHUB
B25: APRIL | D25: POR CHECK IN | E25: 171.82 | H25: 1202.74 | I25: {=E25*W78} -> 171.82 | J25: 1202.74 | K25: {=E25*Y78} -> 0 | P25: WELLHUB
B26: TOÑITO OSNAYA | D26: POR CHECK IN | E26: 171.82 | H26: 1890 | I26: 1890 | J26: 1890.02 | K26: {=E26*Y80} -> 859.1 | O26: TODAS | P26: WELLHUB
B27: URIEL CARDIEL | D27: POR CHECK IN | E27: 171.82 | H27: 1890.02 | I27: {=E27*W92} -> 1030.92 | J27: 1890.02 | K27: {=E27*Y92} -> 1546.38 | P27: WELLHUB
B28: OLIVER OLIVARES | D28: POR CHECK IN | E28: 171.82 | H28: X | I28: X | J28: X | K28: {=E28*Y129} -> 343.64
B29: TOTAL WELLHUB | H29: 4982.76 | I29: 3092.74 | J29: 4982.78 | K29: {=K25+K26+K27+K28} -> 2749.12 | P29: WELLHUB
B30: POR CLASE | C30: POR CLASE | O30: TODAS | P30: $ POR CLASE
B31: VALERIA MENA | C31: 11 MARZO | D31: PAGADA | E31: 75 | F31: SEMANAL | G31: 25 MARZO | H31: 500 | I31: 0 | J31: 500 | O31: UNA | P31: $ POR CLASE
B32: ANGELINA HERNÁNDEZ GARCIA | D32: PAGADA | E32: 75 | F32: POR CLASE | H32: 675 | I32: 1200 | J32: 225 | K32: {=E32*Y109} -> 750 | O32: UNA | P32: $ POR CLASE
B33: VERO JUÁREZ | C33: 21 ENERO | D33: PAGADA | E33: 75 | F33: POR CLASE | H33: 450 | I33: 825 | J33: 750 | K33: {=E33*Y110} -> 525
B34: ARYA CUELLAR | C34: 11 ENERO | D34: PAGADA | E34: 75 | F34: POR CLASE | H34: 375 | I34: 375 | J34: 300 | K34: {=E34*Y102} -> 150
B35: PATRICIO CUELLAR | C35: 11 ENERO | D35: PAGADA | E35: 75 | F35: POR CLASE | H35: 300 | I35: 375 | J35: 300 | K35: {=E35*Y103} -> 150 | O35: UNA | P35: $ POR CLASE
B36: ZULEIKA DE ZENTENO | C36: 14 ENERO | D36: PAGADA | E36: 90 | F36: POR CLASE | H36: 0 | I36: 270 | J36: 1080 | K36: {=E36*Y104} -> 540 | O36: UNA | P36: $ POR CLASE
B37: DANIEL ALBERTANO. ZENTENO | C37: 14 ENERO | D37: PAGADA | E37: 75 | F37: POR CLASE | H37: 0 | I37: 0 | J37: 1080 | K37: {=E37*Y105} -> 150 | O37: UNA | P37: $ POR CLASE
B38: NICOLE ZENTENO | C38: 14 ENERO | D38: PAGADA | E38: 90 | F38: POR CLASE | H38: 0 | I38: 270 | J38: 0 | K38: {=E38*Y106} -> 270 | O38: UNA | P38: $ POR CLASE
B39: CARLOS ERNESTO | C39: 18 MARZO | D39: Debe membresía | E39: 75 | F39: POR CLASE | G39: 18 ABRIL | H39: 300 | I39: 450 | J39: 600 | O39: UNA | P39: $ POR CLASE
B40: YOHAN OROPEZA | C40: 08 ABRIL | D40: X | E40: 175 | F40: POWERLIFTING | G40: 08 ABRIL | H40: 0 | I40: 0 | J40: 0 | K40: 175
B41: TOTAL CLASES | H41: 2975 | I41: 4440 | J41: 6310 | K41: {=SUM(K31:K40)} -> 2710
B42: RECOVERY LAB | C42: RECOVERY. LAB
...
